<?xml version="1.0" encoding="UTF-8"?>
<testng-results skipped="0" failed="2" ignored="0" total="3" passed="1">
  <reporter-output>
  </reporter-output>
  <suite name="Default suite" duration-ms="31303" started-at="2020-11-24T09:44:36Z" finished-at="2020-11-24T09:45:08Z">
    <groups>
    </groups>
    <test name="Default test" duration-ms="31303" started-at="2020-11-24T09:44:36Z" finished-at="2020-11-24T09:45:08Z">
      <class name="test_Case.Test1">
        <test-method status="PASS" signature="setUP()[pri:0, instance:test_Case.Test1@4cf777e8]" name="setUP" is-config="true" duration-ms="13579" started-at="2020-11-24T09:44:36Z" finished-at="2020-11-24T09:44:50Z">
          <reporter-output>
          </reporter-output>
        </test-method> <!-- setUP -->
        <test-method status="PASS" signature="validateTitle()[pri:1, instance:test_Case.Test1@4cf777e8]" name="validateTitle" duration-ms="16704" started-at="2020-11-24T09:44:50Z" finished-at="2020-11-24T09:45:07Z">
          <reporter-output>
          </reporter-output>
        </test-method> <!-- validateTitle -->
        <test-method status="FAIL" signature="ValidateTitle2()[pri:2, instance:test_Case.Test1@4cf777e8]" name="ValidateTitle2" duration-ms="7" started-at="2020-11-24T09:45:07Z" finished-at="2020-11-24T09:45:07Z">
          <exception class="java.lang.AssertionError">
            <message>
              <![CDATA[Test Case Failed expected [Fail] but found [Amazon Sign-In]]]>
            </message>
            <full-stacktrace>
              <![CDATA[java.lang.AssertionError: Test Case Failed expected [Fail] but found [Amazon Sign-In]
at org.testng.Assert.fail(Assert.java:96)
at org.testng.Assert.failNotEquals(Assert.java:776)
at org.testng.Assert.assertEqualsImpl(Assert.java:137)
at org.testng.Assert.assertEquals(Assert.java:118)
at org.testng.Assert.assertEquals(Assert.java:453)
at test_Case.Test1.ValidateTitle2(Test1.java:57)
at sun.reflect.NativeMethodAccessorImpl.invoke0(Native Method)
at sun.reflect.NativeMethodAccessorImpl.invoke(Unknown Source)
at sun.reflect.DelegatingMethodAccessorImpl.invoke(Unknown Source)
at java.lang.reflect.Method.invoke(Unknown Source)
at org.testng.internal.MethodInvocationHelper.invokeMethod(MethodInvocationHelper.java:124)
at org.testng.internal.Invoker.invokeMethod(Invoker.java:583)
at org.testng.internal.Invoker.invokeTestMethod(Invoker.java:719)
at org.testng.internal.Invoker.invokeTestMethods(Invoker.java:989)
at org.testng.internal.TestMethodWorker.invokeTestMethods(TestMethodWorker.java:125)
at org.testng.internal.TestMethodWorker.run(TestMethodWorker.java:109)
at org.testng.TestRunner.privateRun(TestRunner.java:648)
at org.testng.TestRunner.run(TestRunner.java:505)
at org.testng.SuiteRunner.runTest(SuiteRunner.java:455)
at org.testng.SuiteRunner.runSequentially(SuiteRunner.java:450)
at org.testng.SuiteRunner.privateRun(SuiteRunner.java:415)
at org.testng.SuiteRunner.run(SuiteRunner.java:364)
at org.testng.SuiteRunnerWorker.runSuite(SuiteRunnerWorker.java:52)
at org.testng.SuiteRunnerWorker.run(SuiteRunnerWorker.java:84)
at org.testng.TestNG.runSuitesSequentially(TestNG.java:1208)
at org.testng.TestNG.runSuitesLocally(TestNG.java:1137)
at org.testng.TestNG.runSuites(TestNG.java:1049)
at org.testng.TestNG.run(TestNG.java:1017)
at org.testng.remote.AbstractRemoteTestNG.run(AbstractRemoteTestNG.java:114)
at org.testng.remote.RemoteTestNG.initAndRun(RemoteTestNG.java:251)
at org.testng.remote.RemoteTestNG.main(RemoteTestNG.java:77)
]]>
            </full-stacktrace>
          </exception> <!-- java.lang.AssertionError -->
          <reporter-output>
          </reporter-output>
        </test-method> <!-- ValidateTitle2 -->
        <test-method status="FAIL" signature="ValidateTitle3()[pri:3, instance:test_Case.Test1@4cf777e8]" name="ValidateTitle3" duration-ms="8" started-at="2020-11-24T09:45:07Z" finished-at="2020-11-24T09:45:07Z">
          <exception class="java.lang.AssertionError">
            <message>
              <![CDATA[Test Case Failed expected [Fail] but found [Amazon Sign-In]]]>
            </message>
            <full-stacktrace>
              <![CDATA[java.lang.AssertionError: Test Case Failed expected [Fail] but found [Amazon Sign-In]
at org.testng.Assert.fail(Assert.java:96)
at org.testng.Assert.failNotEquals(Assert.java:776)
at org.testng.Assert.assertEqualsImpl(Assert.java:137)
at org.testng.Assert.assertEquals(Assert.java:118)
at org.testng.Assert.assertEquals(Assert.java:453)
at test_Case.Test1.ValidateTitle3(Test1.java:67)
at sun.reflect.NativeMethodAccessorImpl.invoke0(Native Method)
at sun.reflect.NativeMethodAccessorImpl.invoke(Unknown Source)
at sun.reflect.DelegatingMethodAccessorImpl.invoke(Unknown Source)
at java.lang.reflect.Method.invoke(Unknown Source)
at org.testng.internal.MethodInvocationHelper.invokeMethod(MethodInvocationHelper.java:124)
at org.testng.internal.Invoker.invokeMethod(Invoker.java:583)
at org.testng.internal.Invoker.invokeTestMethod(Invoker.java:719)
at org.testng.internal.Invoker.invokeTestMethods(Invoker.java:989)
at org.testng.internal.TestMethodWorker.invokeTestMethods(TestMethodWorker.java:125)
at org.testng.internal.TestMethodWorker.run(TestMethodWorker.java:109)
at org.testng.TestRunner.privateRun(TestRunner.java:648)
at org.testng.TestRunner.run(TestRunner.java:505)
at org.testng.SuiteRunner.runTest(SuiteRunner.java:455)
at org.testng.SuiteRunner.runSequentially(SuiteRunner.java:450)
at org.testng.SuiteRunner.privateRun(SuiteRunner.java:415)
at org.testng.SuiteRunner.run(SuiteRunner.java:364)
at org.testng.SuiteRunnerWorker.runSuite(SuiteRunnerWorker.java:52)
at org.testng.SuiteRunnerWorker.run(SuiteRunnerWorker.java:84)
at org.testng.TestNG.runSuitesSequentially(TestNG.java:1208)
at org.testng.TestNG.runSuitesLocally(TestNG.java:1137)
at org.testng.TestNG.runSuites(TestNG.java:1049)
at org.testng.TestNG.run(TestNG.java:1017)
at org.testng.remote.AbstractRemoteTestNG.run(AbstractRemoteTestNG.java:114)
at org.testng.remote.RemoteTestNG.initAndRun(RemoteTestNG.java:251)
at org.testng.remote.RemoteTestNG.main(RemoteTestNG.java:77)
]]>
            </full-stacktrace>
          </exception> <!-- java.lang.AssertionError -->
          <reporter-output>
          </reporter-output>
        </test-method> <!-- ValidateTitle3 -->
        <test-method status="PASS" signature="endTest()[pri:0, instance:test_Case.Test1@4cf777e8]" name="endTest" is-config="true" duration-ms="909" started-at="2020-11-24T09:45:07Z" finished-at="2020-11-24T09:45:08Z">
          <reporter-output>
          </reporter-output>
        </test-method> <!-- endTest -->
      </class> <!-- test_Case.Test1 -->
    </test> <!-- Default test -->
  </suite> <!-- Default suite -->
</testng-results>
